Workbook

Sheet chart
A1: id | B1: name | C1: description | D1: parent_id | E1: staff_department | F1: manager_id | G1: DATA_Location
A2: 1 | B2: ប្រធ.គណៈកម្មការគ្រប់គ្រងវិទ្យាស្ថាន | E2: N | F2: =INDEX(people!$A$2:$A$300, MATCH(G2,people!$C$2:$C$300, 0)) -> 1680300332 | G2: សេង ស៊ីម
A3: 2 | B3: អនុប្រធ.គណៈកម្មការគ្រប់គ្រងវិទ្យាស្ថាន | D3: =A2 -> 1 | E3: N | F3: =INDEX(people!$A$2:$A$300, MATCH(G3,people!$C$2:$C$300, 0)) -> 1680800830 | G3: ព្រំ បូរ៉ាត
A4: 3 | B4: អនុប្រធ.គណៈកម្មការគ្រប់គ្រងវិទ្យាស្ថាន | D4: =A2 -> 1 | E4: N | F4: =INDEX(people!$A$2:$A$300, MATCH(G4,people!$C$2:$C$300, 0)) -> ​​​​​​​​​​​​​​​​​​​​​​​​​​​​​​​​​​​1740600213 | G4: តាយ ណារិន
A5: 4 | B5: សមាជិកគណៈកម្មការគ្រប់គ្រងវិទ្យាស្ថាន | D5: =$A$3 -> 2 | E5: Y | F5: =INDEX(people!$A$2:$A$300, MATCH(G5,people!$C$2:$C$300, 0)) -> 2690300192 | G5: ស៊ឹម ស៊ីណាត
A6: 5 | B6: សមាជិកគណៈកម្មការគ្រប់គ្រងវិទ្យាស្ថាន | D6: =$A$3 -> 2 | E6: Y | F6: =INDEX(people!$A$2:$A$300, MATCH(G6,people!$C$2:$C$300, 0)) -> 1710300275 | G6: អ៊ុំ កេងម៉េង
A7: 6 | B7: សមាជិកគណៈកម្មការគ្រប់គ្រងវិទ្យាស្ថាន | D7: =$A$3 -> 2 | E7: Y | F7: =INDEX(people!$A$2:$A$300, MATCH(G7,people!$C$2:$C$300, 0)) -> 1931000087 | G7: កាក់ រតនា
A8: 7 | B8: សមាជិកគណៈកម្មការគ្រប់គ្រងវិទ្យាស្ថាន | D8: =$A$4 -> 3 | E8: Y | F8: =INDEX(people!$A$2:$A$300, MATCH(G8,people!$C$2:$C$300, 0)) -> 1800800450 | G8: ព្រហ្ម មុន្នី
A9: 8 | B9: សមាជិកគណៈកម្មការគ្រប់គ្រងវិទ្យាស្ថាន | D9: =$A$4 -> 3 | E9: Y | F9: =INDEX(people!$A$2:$A$300, MATCH(G9,people!$C$2:$C$300, 0)) -> 1800300408 | G9: ឡុង សុវ៉ាង
A10: 9 | B10: សមាជិកគណៈកម្មការគ្រប់គ្រងវិទ្យាស្ថាន | D10: =$A$4 -> 3 | E10: Y | F10: =INDEX(people!$A$2:$A$300, MATCH(G10,people!$C$2:$C$300, 0)) -> 1900300145 | G10: ម៉ៅ កុសល
A11: 10 | B11: សមាជិកគណៈកម្មការគ្រប់គ្រងវិទ្យាស្ថាន | D11: =$A$4 -> 3 | E11: Y | F11: =INDEX(people!$A$2:$A$300, MATCH(G11,people!$C$2:$C$300, 0)) -> 2880300262 | G11: រុន វួចនា
A12: 11 | B12: នាយក​សាលា​បឋម​អនុវត្តន៍ | D12: =A3 -> 2 | E12: N | F12: =INDEX(people!$A$2:$A$300, MATCH(G12,people!$C$2:$C$300, 0)) -> 1720300297 | G12: បេង ហេង
A13: 12 | B13: នាយិការង​សាលា​បឋម​អនុវត្តន៍ | D13: =A12 -> 11 | E13: N | F13: =INDEX(people!$A$2:$A$300, MATCH(G13,people!$C$2:$C$300, 0)) -> 2740300117 | G13: សន សុម៉ាលី
A14: 13 | B14: លេខាធិការ | D14: =$A$13 -> 12 | E14: N | F14: =INDEX(people!$A$2:$A$300, MATCH(G14,people!$C$2:$C$300, 0)) -> 1680300329 | G14: សួង សុគន្ធា
A15: 14 | B15: គណនេយ្យ | D15: =$A$14 -> 13 | E15: N | F15: =INDEX(people!$A$2:$A$300, MATCH(G15,people!$C$2:$C$300, 0)) -> 2940300006 | G15: លី វណ្ណនីដា
A16: 15 | B16: បណ្ណរក្ស | D16: =$A$14 -> 13 | E16: N | F16: =INDEX(people!$A$2:$A$300, MATCH(G16,people!$C$2:$C$300, 0)) -> 2760300055 | G16: ម៉ន សុឃា
A17: 16 | B17: រោងជាង | D17: =$A$14 -> 13 | E17: N | F17: =INDEX(people!$A$2:$A$300, MATCH(G17,people!$C$2:$C$300, 0)) -> 1850300039 | G17: សាត សំអាត
A18: 17 | B18: បំណិនជីវិត | D18: =$A$14 -> 13 | E18: N | F18: =INDEX(people!$A$2:$A$300, MATCH(G18,people!$C$2:$C$300, 0)) -> 1750300287 | G18: ណោ រ៉ា
A19: 18 | B19: ប្រឹក្សាគរុកោសល្យ | D19: =$A$14 -> 13 | E19: N | F19: =INDEX(people!$A$2:$A$300, MATCH(G19,people!$C$2:$C$300, 0)) -> 2910300192 | G19: ខុន ធារី
A20: 19 | B20: ប្រឹក្សាគរុកោសល្យ | D20: =$A$14 -> 13 | E20: N | F20: =INDEX(people!$A$2:$A$300, MATCH(G20,people!$C$2:$C$300, 0)) -> 2980300044 | G20: ម៉ៅ ស្រីណេត
A21: 20 | B21: គ្រូបឋមសិក្សា | D21: =$A$13 -> 12 | E21: N | F21: =INDEX(people!$A$2:$A$300, MATCH(G21,people!$C$2:$C$300, 0)) -> 2780300025 | G21: ហ៊ៅ គីមណៃ
A22: 21 | B22: គ្រូបឋមសិក្សា | D22: =$A$21 -> 20 | E22: N | F22: =INDEX(people!$A$2:$A$300, MATCH(G22,people!$C$2:$C$300, 0)) -> 2980300142 | G22: ឈីន បូណាវត្តី
A23: 22 | B23: គ្រូបឋមសិក្សា | D23: =$A$21 -> 20 | E23: N | F23: =INDEX(people!$A$2:$A$300, MATCH(G23,people!$C$2:$C$300, 0)) -> 2820300159 | G23: ទន់ សុគន្ធា
A24: 23 | B24: គ្រូបឋមសិក្សា | D24: =$A$21 -> 20 | E24: N | F24: =INDEX(people!$A$2:$A$300, MATCH(G24,people!$C$2:$C$300, 0)) -> 2860300021 | G24: សេង​ ​ សុផា
A25: 24 | B25: គ្រូបឋមសិក្សា | D25: =$A$21 -> 20 | E25: N | F25: =INDEX(people!$A$2:$A$300, MATCH(G25,people!$C$2:$C$300, 0)) -> 1870300055 | G25: ចុង ហ្វីនី
A26: 25 | B26: គ្រូបឋមសិក្សា | D26: =$A$21 -> 20 | E26: N | F26: =INDEX(people!$A$2:$A$300, MATCH(G26,people!$C$2:$C$300, 0)) -> 1960300052 | G26: យ៉េន បញ្ញា
A27: 26 | B27: គ្រូបឋមសិក្សា | D27: =$A$21 -> 20 | E27: N | F27: =INDEX(people!$A$2:$A$300, MATCH(G27,people!$C$2:$C$300, 0)) -> 2960300120 | G27: សន សុខឡៃ
A28: 27 | B28: គ្រូបឋមសិក្សា | D28: =$A$21 -> 20 | E28: N | F28: =INDEX(people!$A$2:$A$300, MATCH(G28,people!$C$2:$C$300, 0)) -> 1930300052 | G28: មាស រ៉ាដូ
A29: 28 | B29: គ្រូបឋមសិក្សា | D29: =$A$21 -> 20 | E29: N | F29: =INDEX(people!$A$2:$A$300, MATCH(G29,people!$C$2:$C$300, 0)) -> 2981400029 | G29: ម៉ង់ ចាន់ស៊ាងម៉ី
A30: 29 | B30: គ្រូបឋមសិក្សា | D30: =$A$21 -> 20 | E30: N | F30: =INDEX(people!$A$2:$A$300, MATCH(G30,people!$C$2:$C$300, 0)) -> 2960300101 | G30: ហាក់ សុវណ្ណរ៉ា
A31: 30 | B31: គ្រូបឋមសិក្សា | D31: =$A$21 -> 20 | E31: N | F31: =INDEX(people!$A$2:$A$300, MATCH(G31,people!$C$2:$C$300, 0)) -> 1980300018 | G31: គង់ ណាវីន
A32: 31 | B32: គ្រូកិច្ចសន្យា NGS | D32: =A13 -> 12 | E32: N | F32: =INDEX(people!$A$2:$A$300, MATCH(G32,people!$C$2:$C$300, 0)) -> 2980300154 | G32: មឿន ស៊ីណា
A33: 32 | B33: គ្រូកិច្ចសន្យា NGS | D33: =$A$32 -> 31 | E33: N | F33: =INDEX(people!$A$2:$A$300, MATCH(G33,people!$C$2:$C$300, 0)) -> 2020300019 | G33: ម៉ុន សុខចេង
A34: 33 | B34: គ្រូកិច្ចសន្យា NGS | D34: =$A$32 -> 31 | E34: N | F34: =INDEX(people!$A$2:$A$300, MATCH(G34,people!$C$2:$C$300, 0)) -> 2034800003 | G34: ផៃ ស្រីណុច
A35: 34 | B35: គ្រូកិច្ចសន្យា NGS | D35: =$A$32 -> 31 | E35: N | F35: =INDEX(people!$A$2:$A$300, MATCH(G35,people!$C$2:$C$300, 0)) -> 2980300083 | G35: ភាព រចនា
A36: 35 | B36: គ្រូកិច្ចសន្យា NGS | D36: =$A$32 -> 31 | E36: N | F36: =INDEX(people!$A$2:$A$300, MATCH(G36,people!$C$2:$C$300, 0)) -> 1020300008 | G36: ចាន់ ថាភិរម្យ
A37: 36 | B37: គ្រូកិច្ចសន្យា NGS | D37: =$A$32 -> 31 | E37: N | F37: =INDEX(people!$A$2:$A$300, MATCH(G37,people!$C$2:$C$300, 0)) -> 2980300081 | G37: ម៉ាន់ ស្រីកែវ
A38: 37 | B38: ប្រធ.​ការិយាល័យរដ្ឋបាល និងធនធានមនុស្ស | D38: =A3 -> 2 | E38: N | F38: =INDEX(people!$A$2:$A$300, MATCH(G38,people!$C$2:$C$300, 0)) -> 2680300182 | G38: សឹង ហ៊ីណារិន
A39: 38 | B39: អនុប្រធ.​ការិយាល័យរដ្ឋបាល និងធនធានមនុស្ស | D39: =A38 -> 37 | E39: N | F39: =INDEX(people!$A$2:$A$300, MATCH(G39,people!$C$2:$C$300, 0)) -> 1960300210 | G39: ហេម សោភា
A40: 39 | B40: បុគ្គលិក | D40: =A39 -> 38 | E40: N | F40: =INDEX(people!$A$2:$A$300, MATCH(G40,people!$C$2:$C$300, 0)) -> 1680300331 | G40: ជូ សុផានី
...

Sheet people
A1: id | B1: name | C1: tittle | D1: photo | E1: en_name | F1: sex | G1: functionName | H1: field_Phone | I1: field_Email | J1: field_Homepage | K1: field_Country | L1: field_City | M1: field_Street
A2: 1680300332 | B2: =IF(F2="ប្រុស","លោក "&C2,"លោកស្រី "&C2) -> លោក សេង ស៊ីម | C2: សេង ស៊ីម | D2: seng.sim | E2: Seng Sim | F2: ប្រុស | H2: =VLOOKUP(E2,data!$C$2:$U$103,5,FALSE) -> 012 989 336
A3: ​​​​​​​​​​​​​​​​​​​​​​​​​​​​​​​​​​​1740600213 | B3: =IF(F3="ប្រុស","លោក "&C3,"លោកស្រី "&C3) -> លោក តាយ ណារិន | C3: តាយ ណារិន | D3: tay.narin | E3: Tay Narin | F3: ប្រុស | H3: =VLOOKUP(E3,data!$C$2:$U$103,5,FALSE) -> 016 720 128
A4: 1710300275 | B4: =IF(F4="ប្រុស","លោក "&C4,"លោកស្រី "&C4) -> លោក អ៊ុំ កេងម៉េង | C4: អ៊ុំ កេងម៉េង | D4: um.kengmeng | E4: Um Kengmeng | F4: ប្រុស | H4: =VLOOKUP(E4,data!$C$2:$U$103,5,FALSE) -> 012 218 911
A5: 1800300530 | B5: =IF(F5="ប្រុស","លោក "&C5,"លោកស្រី "&C5) -> លោក ហ៊ាត់ ប៊ុនហឿង | C5: ហ៊ាត់ ប៊ុនហឿង | D5: hort.bunhoeurng | E5: Hort Bunhoeurng | F5: ប្រុស | H5: =VLOOKUP(E5,data!$C$2:$U$103,5,FALSE) -> 012 315 091
A6: 2680300154 | B6: =IF(F6="ប្រុស","លោក "&C6,"លោកស្រី "&C6) -> លោកស្រី អ៊ុក វណ្ណថាត | C6: អ៊ុក វណ្ណថាត | D6: ouk.vanthat | E6: Ouk Vanthat | F6: ស្រី | H6: =VLOOKUP(E6,data!$C$2:$U$103,5,FALSE) -> 076 999 3832
A7: 1680300331 | B7: =IF(F7="ប្រុស","លោក "&C7,"លោកស្រី "&C7) -> លោក ជូ សុផានី | C7: ជូ សុផានី | D7: chou.sophany | E7: Chou Sophany | F7: ប្រុស | H7: =VLOOKUP(E7,data!$C$2:$U$103,5,FALSE) -> 099 880 110
A8: 1750300438 | B8: =IF(F8="ប្រុស","លោក "&C8,"លោកស្រី "&C8) -> លោក ខុន គង់ | C8: ខុន គង់ | D8: khon.kong | E8: Khon Kong | F8: ប្រុស | H8: =VLOOKUP(E8,data!$C$2:$U$103,5,FALSE) -> 092 689 922
A9: 1790300234 | B9: =IF(F9="ប្រុស","លោក "&C9,"លោកស្រី "&C9) -> លោក ហ៊ឹង សុខចាន់ | C9: ហ៊ឹង សុខចាន់ | D9: hoeung.sokchann | E9: Hoeung Sokchann | F9: ប្រុស | H9: =VLOOKUP(E9,data!$C$2:$U$103,5,FALSE) -> 078 829 990
A10: 2820300049 | B10: =IF(F10="ប្រុស","លោក "&C10,"លោកស្រី "&C10) -> លោកស្រី ឱ ភិរ៉ាណ | C10: ឱ ភិរ៉ាណ | D10: or.phiran | E10: Or Phiran | F10: ស្រី | H10: =VLOOKUP(E10,data!$C$2:$U$103,5,FALSE) -> 012 626 057
A11: 2720300109 | B11: =IF(F11="ប្រុស","លោក "&C11,"លោកស្រី "&C11) -> លោកស្រី ចិន ផល្លា | C11: ចិន ផល្លា | D11: chen.phalla | E11: Chen Phalla | F11: ស្រី | H11: =VLOOKUP(E11,data!$C$2:$U$103,5,FALSE) -> 096 570 4177
A12: 1660300189 | B12: =IF(F12="ប្រុស","លោក "&C12,"លោកស្រី "&C12) -> លោក យ៉ែម រុំផា | C12: យ៉ែម រុំផា | D12: yem.rompha | E12: Yem Rompha | F12: ប្រុស | H12: =VLOOKUP(E12,data!$C$2:$U$103,5,FALSE) -> 012 897 651
A13: 2670300101 | B13: =IF(F13="ប្រុស","លោក "&C13,"លោកស្រី "&C13) -> លោកស្រី ឡាង គីមសេង | C13: ឡាង គីមសេង | D13: lang.kimseng | E13: Lang Kimseng | F13: ស្រី | H13: =VLOOKUP(E13,data!$C$2:$U$103,5,FALSE) -> 0
A14: 1820300233 | B14: =IF(F14="ប្រុស","លោក "&C14,"លោកស្រី "&C14) -> លោក ហេង សីហា | C14: ហេង សីហា | D14: heng.seiha | E14: Heng Seiha | F14: ប្រុស | H14: =VLOOKUP(E14,data!$C$2:$U$103,5,FALSE) -> 092 402 727
A15: 1890700240 | B15: =IF(F15="ប្រុស","លោក "&C15,"លោកស្រី "&C15) -> លោក គុំ រំដោះ | C15: គុំ រំដោះ | D15: kum.romdoh | E15: Kum Romdoh | F15: ប្រុស | H15: =VLOOKUP(E15,data!$C$2:$U$103,5,FALSE) -> 017 887 400
... A102: 2000300183 | B102: =IF(F102="ប្រុស","លោក "&C102,"លោកស្រី "&C102) -> លោកស្រី លី ស្រីពៅ | C102: លី ស្រីពៅ | D102: ly.sreypov | E102: Ly Sreypov | F102: ស្រី | H102: =VLOOKUP(E102,data!$C$2:$U$103,5,FALSE) -> 096​ 816 1466
A103: 1990300147 | B103: =IF(F103="ប្រុស","លោក "&C103,"លោកស្រី "&C103) -> លោក ធុយ សុភត្រ្តា | C103: ធុយ សុភត្រ្តា | D103: thuy.sopheaktra | E103: Thuy Sopheaktra | F103: ប្រុស | H103: =VLOOKUP(E103,data!$C$2:$U$203,5,FALSE) -> 088 ​913 0994
A104: 100001 | B104: =IF(F104="ប្រុស","លោក "&C104,"លោកស្រី "&C104) -> លោក ថេង ធីណា | C104: ថេង ធីណា | D104: theng.thina | E104: Theng Thina | F104: ប្រុស | H104: =VLOOKUP(E104,data!$C$2:$U$203,5,FALSE) -> 0
A105: 1720300297 | B105: =IF(F105="ប្រុស","លោក "&C105,"លោកស្រី "&C105) -> លោក បេង ហេង | C105: បេង ហេង | D105: beng.heng | E105: Beng Heng | F105: ប្រុស | H105: =VLOOKUP(E105,data!$C$2:$U$203,5,FALSE) -> 061 678 720
A106: 2740300117 | B106: =IF(F106="ប្រុស","លោក "&C106,"លោកស្រី "&C106) -> លោកស្រី សន សុម៉ាលី | C106: សន សុម៉ាលី | D106: san.somaly | E106: San Somaly | F106: ស្រី | H106: =VLOOKUP(E106,data!$C$2:$U$203,5,FALSE) -> 061 697 563
A107: 2980300142 | B107: =IF(F107="ប្រុស","លោក "&C107,"លោកស្រី "&C107) -> លោកស្រី ឈីន បូណាវត្តី | C107: ឈីន បូណាវត្តី | D107: chhin.bonavattey | E107: Chhin Bonavattey | F107: ស្រី | H107: =VLOOKUP(E107,data!$C$2:$U$203,5,FALSE) -> 061 647 862
A108: 1750300287 | B108: =IF(F108="ប្រុស","លោក "&C108,"លោកស្រី "&C108) -> លោក ណោ រ៉ា | C108: ណោ រ៉ា | D108: nor.ra | E108: Nor Ra | F108: ប្រុស | H108: =VLOOKUP(E108,data!$C$2:$U$203,5,FALSE) -> 061 993 277
A109: 2760300055 | B109: =IF(F109="ប្រុស","លោក "&C109,"លោកស្រី "&C109) -> លោកស្រី ម៉ន សុឃា | C109: ម៉ន សុឃា | D109: man.sokhea | E109: Man Sokhea | F109: ស្រី | H109: =VLOOKUP(E109,data!$C$2:$U$203,5,FALSE) -> 061 654 592
A110: 2780300025 | B110: =IF(F110="ប្រុស","លោក "&C110,"លោកស្រី "&C110) -> លោកស្រី ហ៊ៅ គីមណៃ | C110: ហ៊ៅ គីមណៃ | D110: hov.kimnay | E110: Hov Kimnay | F110: ស្រី | H110: =VLOOKUP(E110,data!$C$2:$U$203,5,FALSE) -> 061 533 873
A111: 2820300159 | B111: =IF(F111="ប្រុស","លោក "&C111,"លោកស្រី "&C111) -> លោកស្រី ទន់ សុគន្ធា | C111: ទន់ សុគន្ធា | D111: tun.sokunthea | E111: Tun Sokunthea | F111: ស្រី | H111: =VLOOKUP(E111,data!$C$2:$U$203,5,FALSE) -> 061 640 844
A112: 1850300039 | B112: =IF(F112="ប្រុស","លោក "&C112,"លោកស្រី "&C112) -> លោក សាត សំអាត | C112: សាត សំអាត | D112: sat.somat | E112: Sat Somat | F112: ប្រុស | H112: =VLOOKUP(E112,data!$C$2:$U$203,5,FALSE) -> 061 674 926
A113: 2860300021 | B113: =IF(F113="ប្រុស","លោក "&C113,"លោកស្រី "&C113) -> លោកស្រី សេង​ ​ សុផា | C113: សេង​ ​ សុផា | D113: seng.sopha | E113: Seng Sopha | F113: ស្រី | H113: =VLOOKUP(E113,data!$C$2:$U$203,5,FALSE) -> 061 576 591
A114: 1870300055 | B114: =IF(F114="ប្រុស","លោក "&C114,"លោកស្រី "&C114) -> លោក ចុង ហ្វីនី | C114: ចុង ហ្វីនី | D114: chong.finy | E114: Chong Finy | F114: ប្រុស | H114: =VLOOKUP(E114,data!$C$2:$U$203,5,FALSE) -> 062 103 153
... A125: 100002 | B125: =IF(F125="ប្រុស","លោក "&C125,"លោកស្រី "&C125) -> លោក យក់ ឆៃយ៉ា | C125: យក់ ឆៃយ៉ា | D125: yuk.chaiya | E125: Yuk Chaiya | F125: ប្រុស | H125: =VLOOKUP(E125,data!$C$2:$U$203,5,FALSE) -> 0
A126: 2980300154 | B126: =IF(F126="ប្រុស","លោក "&C126,"លោកស្រី "&C126) -> លោកស្រី មឿន ស៊ីណា | C126: មឿន ស៊ីណា | D126: moeurn.sina | E126: Moeurn Sina | F126: ស្រី | H126: 097 7019438
A127: 2020300019 | B127: =IF(F127="ប្រុស","លោក "&C127,"លោកស្រី "&C127) -> លោកស្រី ម៉ុន សុខចេង | C127: ម៉ុន សុខចេង | D127: mon.sokcheng | E127: Mon Sokcheng | F127: ស្រី | H127: 066 545137
A128: 2034800003 | B128: =IF(F128="ប្រុស","លោក "&C128,"លោកស្រី "&C128) -> លោកស្រី ផៃ ស្រីណុច | C128: ផៃ ស្រីណុច | D128: phai.sreynoch | E128: Phai Sreynoch | F128: ស្រី | H128: 088 6724911
A129: 2980300083 | B129: =IF(F129="ប្រុស","លោក "&C129,"លោកស្រី "&C129) -> លោកស្រី ភាព រចនា | C129: ភាព រចនា | D129: pheap.rachana | E129: Pheap Rachana | F129: ស្រី | H129: 010 990963
A130: 1020300008 | B130: =IF(F130="ប្រុស","លោក "&C130,"លោកស្រី "&C130) -> លោក ចាន់ ថាភិរម្យ | C130: ចាន់ ថាភិរម្យ | D130: chan.thapherom | E130: Chan Thapherom | F130: ប្រុស | H130: 098 331517
A131: 2980300081 | B131: =IF(F131="ប្រុស","លោក "&C131,"លោកស្រី "&C131) -> លោកស្រី ម៉ាន់ ស្រីកែវ | C131: ម៉ាន់ ស្រីកែវ | D131: mann.sreykeo | E131: Mann Sreykeo | F131: ស្រី | H131: 096 2291467

Sheet assignment

Sheet data
A1: ល.រ | B1: នាម គោត្តនាម | C1: ឈ្មោះជាអក្សរឡាតាំង | D1: ភេទ | E1: ថ្ងៃខែឆ្នាំកំណើត | F1: អត្តលេខមន្រ្តី | G1: លេខទូរសព្ទ | H1: លេខគណនេយ្យបៀរវត្ស | I1: ខេត្ត | J1: ប្រភេទកាំ | K1: តួនាទី | L1: ដើម | N1: ចុងក្រោយ | P1: កំពុងបន្តការសិក្សា | S1: ឯកទេសដើម និង ចុងក្រោយ | T1: មុខវិជ្ជាបង្រៀន ជាក់ស្ដែង | U1: ផ្សេងៗ
A2: 1 | B2: ព្រំ បូរ៉ាត | C2: Prom Borath | D2: ប | E2: 25123 | F2: 1680800830 | G2: 012 433 143 | H2: 10000165514919 | I2: កំពង់ចាម | J2: ក.១.៦ | K2: នាយក | L2: អក្សរសាស្ដ្រខ្មែរ | M2: បរិញ្ញាបត្រ | N2: វិទ្យាសាស្ត្រអប់រំ | O2: បរិញ្ញាបត្រជាន់ខ្ពស់ | R2: ថវិកាផ្ទាល់ខ្លួន | T2: មិនបង្រៀន
A3: 2 | B3: ស៊ឹម ស៊ីណាត | C3: Sim Sinath | D3: ស | E3: 25515 | F3: 2690300192 | G3: 077 559 967 | H3: 10000165298515 | I3: កំពង់ចាម | J3: ក .២.១ | K3: នាយិការង | L3: គណិតវិទ្យា | M3: បរិញ្ញាបត្រ | N3: វិទ្យាសាស្ត្រអប់រំ | O3: បរិញ្ញាបត្រជាន់ខ្ពស់ | R3: ថវិកាផ្ទាល់ខ្លួន | T3: មិនបង្រៀន
A4: 3 | B4: ព្រហ្ម មុន្នី | C4: Prum Mony | D4: ប | E4: 29540 | F4: 1800800450 | G4: 092 737 648 | H4: 10000165503414 | I4: កំពង់ចាម | J4: ក.២.២ | K4: នាយករង | L4: ចិត្តវិទ្យា | M4: បរិញ្ញាបត្រ | N4: ចិត្តវិទ្យា | O4: បរិញ្ញាបត្រ | R4: ថវិកាផ្ទាល់ខ្លួន | T4: មិនបង្រៀន
A5: 4 | B5: សេង សត្យា | C5: Seng Sathia | D5: ប | E5: 30449 | F5: 1831200363 | G5: 010 420 637 | H5: 10000165492818 | I5: កំពង់ចាម | J5: ក.២.២ | K5: ប្រធាន | L5: កសិកម្ម | M5: បរិញ្ញាបត្រ | N5: វិទ្យាសាស្ត្រអប់រំ | O5: បរិញ្ញាបត្រជាន់ខ្ពស់ | R5: ថវិកាផ្ទាល់ខ្លួន | T5: មិនបង្រៀន
A6: 5 | B6: តាំង ស៊ីភឿន | C6: Taing Siphoeurn | D6: ប | E6: 25274 | F6: 1690300388 | G6: 012 236 891 | H6: 10000165446212 | I6: កំពង់ចាម | J6: ខ.1.6 | K6: គ្រូឧទ្ទេស | L6: ប្រវត្តិវិទ្យា | M6: មធ្យមសិក្សាបឋមភូមិ | N6: ប្រវត្តិវិទ្យា | O6: បរិញ្ញាបត្រជាន់ខ្ពស់ | R6: ថវិកាផ្ទាល់ខ្លួន | T6: បង្រៀន | V6: កិច្ចព្រមព្រៀង BA+1
A7: 6 | B7: ហ៊ង សុខលាភ | C7: Horng Sokleap | D7: ប | E7: 25326 | F7: 1690300603 | G7: 017 225 545 | H7: 10000166471919 | I7: កំពង់ចាម | J7: ខ.២.៤ | K7: អនុប្រធាន | L7: ប្រវត្តិវិទ្យា | M7: មធ្យមសិក្សាទុតិយភូមិ | N7: វិទ្យាសាស្ត្រអប់រំ | O7: បរិញ្ញាបត្រជាន់ខ្ពស់ | R7: ថវិកាផ្ទាល់ខ្លួន | T7: មិនបង្រៀន
A8: 7 | B8: ទេព ជីវសុទ្ធា | C8: Tep Chivaksothea | D8: ប | E8: 24907 | F8: 1680300367 | G8: 092 902 511 | H8: 10000165441313 | I8: កំពង់ចាម | J8: ក.១.១ | K8: បណ្ណារក្ស | L8: ចិត្តគរុកោសល្យ | M8: មធ្យមសិក្សាទុតិយភូមិ | N8: វិទ្យាសាស្ត្រអប់រំ | O8: បរិញ្ញាបត្រជាន់ខ្ពស់ | R8: ថវិកាផ្ទាល់ខ្លួន | T8: មិនបង្រៀន
A9: 8 | B9: ហម ហ្គេចលាង | C9: Ham Guechleang | D9: ស | E9: 24991 | F9: 2680300175 | G9: 012 584 338 | H9: 10000165498010 | I9: កំពង់ចាម | J9: ខ ១ ៣ | K9: បណ្ណារក្ស | L9: អក្សរសាស្ដ្រខ្មែរ | M9: មធ្យមសិក្សាទុតិយភូមិ | N9: អក្សរសាស្រ្តខ្មែរ | O9: បរិញ្ញាបត្រ | R9: ថវិកាផ្ទាល់ខ្លួន | T9: មិនបង្រៀន
A10: 9 | B10: កាក់ រតនា | C10: Kak Ratana | D10: ប | E10: 34275 | F10: 1931000087 | G10: 015 612 512 | H10: 00010296351129 | I10: កំពង់ចាម | J10: ក.៣.៤ | K10: មន្ដ្រី | L10: មន្ត្រីគ្រប់គ្រងរដ្ឋបាល | M10: បរិញ្ញាបត្រ | N10: គ្រប់គ្រង | O10: បរិញ្ញាបត្រជាន់ខ្ពស់ | R10: ថវិកាផ្ទាល់ខ្លួន | T10: បង្រៀន | V10: កិច្ចព្រមព្រៀង BA+1
A11: 10 | B11: សឹង​ ហ៊ីណារិន | C11: Soeung Hynarin | D11: ស | E11: 24857 | F11: 2680300182 | G11: 087 797 776 | H11: 10000165520818 | I11: កំពង់ចាម | J11: ខ.៣.២ | K11: មន្ដ្រី | L11: ខ្មែរ-គេហកិច្ច | M11: មធ្យមសិក្សាទុតិយភូមិ | N11: ខ្មែរ-គេហកិច្ច | O11: មធ្យមសិក្សាទុតិយភូមិ | T11: មិនបង្រៀន
A12: 11 | B12: ឌឿន អ៊ី | C12: Doeun Y | D12: ប | E12: 31518 | F12: 1860300283 | G12: 099 283 783 | H12: 10000045408424 | I12: កំពង់ចាម | J12: ក.២.១ | K12: មន្ដ្រី | L12: ICT បណ្ណាល័យ | M12: បរិញ្ញាបត្រ | N12: វិទ្យាសាស្ត្រអប់រំ | O12: បរិញ្ញាបត្រជាន់ខ្ពស់ | R12: ថវិកាផ្ទាល់ខ្លួន | T12: បង្រៀន | V12: កិច្ចព្រមព្រៀង BA+1
A13: 12 | B13: ថូ សាវុធ | C13: Tho Savuth | D13: ប | E13: 25267 | F13: 1690300349 | G13: 011 760 236 | H13: 10000016861010 | I13: កំពង់ចាម | J13: ខ.៣.៣ | K13: មន្ដ្រី | L13: ខ្មែរ-ពលរដ្ឋ | M13: មធ្យមសិក្សាទុយភូមិ | N13: ខ្មែរ-ពលរដ្ឋ | O13: មធ្យមសិក្សាទុយភូមិ | T13: មិនបង្រៀន
A14: 13 | B14: ហេម សោភា | C14: Hem Sorphea | D14: ប | E14: 35192 | F14: 1960300210 | G14: 016 549 414 | H14: 10000291865219 | I14: កំពង់ចាម | J14: ក.៣.៤ | K14: មន្ដ្រី | L14: មន្ត្រីគ្រប់គ្រងរដ្ឋបាល | M14: បរិញ្ញាបត្រ | N14: រដ្ឋបាលសាធារណៈ | O14: បរិញ្ញាបត្រជាន់ខ្ពស់ | R14: ថវិកាផ្ទាល់ខ្លួន | T14: មិនបង្រៀន
A15: 14 | B15: ប៊ុន ច័ន្ទសុគន្ធា | C15: Bun Chan Sokunthea | D15: ស | E15: 29293 | F15: 2800300234 | G15: 012​ 530 379 | H15: 10000045319323 | I15: កំពង់ចាម | J15: ខ.៣.៣ | K15: មន្ដ្រី | L15: គេហកិច្ច | M15: មធ្យមសិក្សាទុយភូមិ | N15: ទំនាក់ទំនង | O15: បរិញ្ញាបត្រ | R15: ថវិកាផ្ទាល់ខ្លួន | T15: មិនបង្រៀន
A16: 15 | B16: មិត្ត ណារ៉េត | C16: Mith Nareth | D16: ស | E16: 25118 | F16: 2680300173 | G16: 012 550 812 | H16: 10000067479616 | I16: កំពង់ចាម | J16: ក.១.៤ | K16: គ្រូឧទ្ទេស | L16: មត្តេយ្យ | M16: មធ្យមសិក្សាទុយភូមិ | N16: មត្តេយ្យ | O16: មធ្យមសិក្សាទុយភូមិ | R16: រដ្ឋាភិបាល | T16: បង្រៀន | U16: វិទ្យាសាស្រ្ត
A17: 16 | B17: ឃាង ចាន់ដេត | C17: Kheang Chandeth | D17: ស | E17: 32033 | F17: 2871400116 | G17: 015 953 435 | H17: 10000026043818 | I17: កំពង់ចាម | J17: ក.៣.១ | K17: គ្រូឧទ្ទេស | L17: ជីវវិទ្យា | M17: បរិញ្ញាបត្រ | N17: ជីវវិទ្យា | O17: បរិញ្ញាបត្រ | T17: បង្រៀន | U17: វិទ្យាសាស្ត្រអនុវត្ត
A18: 17 | B18: ឃិត លីដា | C18: Khit Lida | D18: ប | E18: 31268 | F18: 1850800312 | G18: 098​​ 6161 63 | H18: 10000165294010 | I18: កំពង់ចាម | J18: ក.៣.១ | K18: គ្រូឧទ្ទេស | L18: តុបតែងលម្អរ | M18: បរិញ្ញាបត្រ | N18: គំនូ | O18: បរិញ្ញាបត្រ | R18: ក២៤ | T18: បង្រៀន | U18: កសិកម្ម
A19: 18 | B19: ជា បញ្ញា | C19: Chea Phannha | D19: ប | E19: 33169 | F19: 1901200129 | G19: 089 930 667 | H19: 10000197599010 | I19: កំពង់ចាម | J19: ក.២.២ | K19: គ្រូឧទ្ទេស | L19: គណិតវិទ្យា | M19: បរិញ្ញាបត្រ | N19: គណិតវិទ្យា | O19: បរិញ្ញាបត្រជាន់ខ្ពស់ | R19: គម្រោង TUP | T19: បង្រៀន | U19: គណិតវិទ្យា
A20: 19 | B20: មុំ វិចិត្រា | C20: Mom Vichettra | D20: ប | E20: 33109 | F20: 1901200130 | G20: 097 248 6868 | H20: 10000197026111 | I20: កំពង់ចាម | J20: ក.៣.២ | K20: គ្រូឧទ្ទេស | L20: ចិត្តវិទ្យា ភាសាអង់គ្លេស | M20: បរិញ្ញាបត្រ | N20: វិទ្យាសាស្ត្រអប់រំ | O20: បរិញ្ញាបត្រជាន់ខ្ពស់ | R20: ថវិការផ្ទាល់ខ្លួន | T20: បង្រៀន | U20: ចិត្តវិទ្យា និង គរុកោសល្យ
A21: 20 | B21: ផល្លា សុម៉ាលីណា | C21: Phalla Somalina | D21: ស | E21: 33046 | F21: 2900300321 | G21: 015 440 254 | H21: 10000197073111 | I21: កំពង់ចាម | J21: ក.៣.១ | K21: គ្រូឧទ្ទេស | L21: អក្សរសាស្ដ្រខ្មែរ | M21: បរិញ្ញាបត្រ | N21: អក្សរសាស្ដ្រខ្មែរ | O21: បរិញ្ញាបត្រជាន់ខ្ពស់ | R21: TUP | T21: បង្រៀន | U21: ភាសាខ្មែរ
A22: 21 | B22: ញឹម ស៊ាងលាភ | C22: Gnim Seangleap | D22: ប | E22: 31175 | F22: 1850300085 | G22: 078 600 636 | H22: 10000170805010 | I22: កំពង់ចាម | J22: ក.៣.១ | K22: គ្រូឧទ្ទេស | L22: ប្រវត្តិវិទ្យា ភូមិវិទ្យា | M22: បរិញ្ញាបត្រ | N22: ប្រវត្តិវិទ្យា | O22: បរិញ្ញាបត្រជាន់ខ្ពស់ | R22: ថវិកាផ្ទាល់ខ្លួន | T22: បង្រៀន | U22: ប្រវត្តិវិទ្យា ភូមិវិទ្យា
A23: 22 | B23: ជឹង លីដា | C23: Ching Lida | D23: ស | E23: 32011 | F23: 2870300008 | G23: 017 661 686 | H23: 10000054775111 | I23: កំពង់ចាម | J23: ក.៣.២ | K23: គ្រូឧទ្ទេស | L23: ប្រវត្តិវិទ្យា | M23: បរិញ្ញាបត្រ | N23: ប្រវត្តវិទ្យា | O23: បរិញ្ញាបត្រជាន់ខ្ពស់ | R23: ថវិកាផ្ទាល់ខ្លួន | T23: បង្រៀន | U23: ប្រវត្តវិទ្យា ភូមិវិទ្យា
A24: 23 | B24: ឃៀង អេងស៊ីម | C24: Kheang Engsim | D24: ស | E24: 24814 | F24: 2670800184 | G24: 011 403 688 | H24: 10000165500717 | I24: កំពង់ចាម | J24: ក.២.៣ | K24: គ្រូឧទ្ទេស | L24: ភូមិ ប្រវត្តិ | M24: មធ្យមសិក្សាទុយភូមិ | N24: អក្សរសាស្ត្រខ្មែរ | O24: បរិញ្ញាបត្រ | R24: ថវិកាផ្ទាល់ខ្លួន | T24: បង្រៀន | U24: អក្សរសាស្ត្រខ្មែរ
A25: 24 | B25: កេត ធីតា | C25: Keth Thyda | D25: ស | E25: 30458 | F25: 2830300017 | G25: 012 933 475 | H25: 34470169075416 | I25: កំពង់ចាម | J25: ក.២.២ | K25: គ្រូឧទ្ទេស | L25: ភាសាអង់គ្លេស | M25: បរិញ្ញាបត្រ | N25: អង់គ្លេស | O25: បរិញ្ញាបត្រជាន់ខ្ពស់ | R25: ថវិកាផ្ទាល់ខ្លួន | T25: បង្រៀន | U25: អង់គ្លេស
A26: 25 | B26: មឿន សុខា | C26: Moeun Sokha | D26: ស | E26: 31433 | F26: 2860300359 | G26: 092 833681 | H26: 10000041490119 | I26: កំពង់ចាម | J26: ក.៣.៣ | K26: គ្រូឧទ្ទេស | L26: ចិត្តគរុកោសល្យ | M26: បរិញ្ញាបត្រ | N26: ចិត្តវិទ្យា | O26: បរិញ្ញាបត្រ | R26: ថវិកាផ្ទាល់ខ្លួន | T26: បង្រៀន | U26: ចិត្តគរុកោសល្យ
A27: 26 | B27: ស្រ៊ុន សុភក្រ្ត | C27: Srun Sopheak | D27: ប | E27: 30805 | F27: 1840300396 | G27: 061 414 646 | H27: 10000165436616 | I27: កំពង់ចាម | J27: ក.៣.១ | K27: គ្រូឧទ្ទេស | L27: គំនូរវិចិត្រកម្ម | M27: បរិញ្ញាបត្រ | N27: គំនូរវិចិត្រកម្ម | O27: បរិញ្ញាបត្រ | R27: ថវិកាផ្ទាល់ខ្លួន | T27: បង្រៀន | U27: កសិកម្ម
A28: 27 | B28: កន ឈុននី | C28: Kan Chhunny | D28: ស | E28: 25600 | F28: 2700300301 | G28: 092 740​ ​682 | H28: 10000165508111 | I28: កំពង់ចាម | J28: ខ.២.១ | K28: គ្រូឧទ្ទេស | L28: អក្សរសាស្ដ្រខ្មែរ | M28: មធ្យមសិក្សាបឋមភូមិ | N28: អក្សរសាស្រ្តខ្មែរ | O28: មធ្យមសិក្សាបឋមភូមិ | T28: បង្រៀន | U28: ភាសាខ្មែរ
A29: 28 | B29: ផាន់ ហាច | C29: Phann Hach | D29: ប | E29: 25331 | F29: 1690300442 | G29: 011 205 871 | H29: 10000165468717 | I29: កំពង់ចាម | J29: ខ.១.៦ | K29: គ្រូឧទ្ទេស | L29: គណិតវិទ្យា | M29: មធ្យមសិក្សាទុយភូមិ | N29: គណិតវិទ្យា | O29: បរិញ្ញាបត្រជាន់ខ្ពស់ | R29: ថវិកាផ្ទាល់ខ្លួន | T29: បង្រៀន | U29: គណិតវិទ្យា
A30: 29 | B30: សឹង ហ៊ីណារុំ | C30: Soeung Hynarom | D30: ប | E30: 25268 | F30: 1690300322 | G30: 096 627 8992 | H30: 10000165495919 | I30: កំពង់ចាម | J30: ខ.២ ១ | K30: គ្រូឧទ្ទេស | L30: គណិតវិទ្យា | M30: មធ្យមសិក្សាទុយភូមិ | N30: គ្រប់គ្រង | O30: បរិញ្ញាបត្រ | R30: ថវិកាផ្ទាល់ខ្លួន | T30: បង្រៀន | U30: គណិតវិទ្យា
A31: 30 | B31: ឃីម វ៉ាន់ឌី | C31: Khim Vanndy | D31: ប | E31: 31919 | F31: 1870300100 | G31: 086 572 451 | H31: 10000166466717 | I31: កំពង់ចាម | J31: ខ.២.១ | K31: គ្រូឧទ្ទេស | L31: បារាំង ខ្មែរ | M31: មធ្យមសិក្សាទុយភូមិ | N31: អក្សរសាស្ត្រខ្មែរ | O31: បរិញ្ញាបត្រ | P31: អប់រំកម្រិតបឋម | Q31: បរិញ្ញាបត្រជាន់ខ្ពស់ | R31: UNESCO | T31: បង្រៀន | U31: ស្រាវជ្រាវអប់រំ ,កុំព្យូទ័រ
A32: 31 | B32: ឡុង ភិរម្យ | C32: Long Phirom | D32: ស | E32: 29356 | F32: 2800300061 | G32: 016 376 387 | H32: 10000165432515 | I32: កំពង់ចាម | J32: ខ.១.៥ | K32: គ្រូឧទ្ទេស | L32: គេហ សីលធម៌ | M32: មធ្យមសិក្សាទុយភូមិ | N32: អក្សរសាស្ត្រខ្មែរ | O32: បរិញ្ញាបត្រ | R32: ថវិការផ្ទាល់ខ្លួន | T32: បង្រៀន | U32: សីលធម៌ពលរដ្ឋ
A33: 32 | B33: កង ថុល | C33: Kang Thol | D33: ប | E33: 26973 | F33: 1730300451 | G33: 092 808 363 | H33: 10000165475313 | I33: កំពង់ចាម | J33: ខ.២.២ | K33: គ្រូឧទ្ទេស | L33: កីឡា | M33: មធ្យមសិក្សាបឋមភូមិ | N33: កីឡា | O33: មធ្យមសិក្សាបឋមភូមិ | R33: ថវិកាក្រសួង | T33: បង្រៀន | U33: កីឡា
A34: 33 | B34: សួន សុម៉ារ៉ា | C34: Suon Somara | D34: ស | E34: 30326 | F34: 2830300078 | G34: 012 576 434 | H34: 10000166475616 | I34: កំពង់ចាម | J34: ខ.២.១ | K34: គ្រូឧទ្ទេស | L34: ខ្មែរ គេហវិទ្យា | M34: មធ្យមសិក្សាទុយភូមិ | N34: អក្សរសាស្ដ្រខ្មែរ | O34: បរិញ្ញាបត្រជាន់ខ្ពស់ | R34: ថវិកាផ្ទាល់ខ្លួន | T34: បង្រៀន | U34: ភាសាខ្មែរ
A35: 34 | B35: គឹម សុកញ្ញា | C35: Kim Sokanha | D35: ស | E35: 29899 | F35: 2810300025 | G35: 017 544 243 | H35: 10000165484515 | I35: កំពង់ចាម | J35: ខ.២.១ | K35: គ្រូឧទ្ទេស | L35: ភាសាអង់គ្លេស | M35: មធ្យមសិក្សាទុតិយភូមិ | N35: ភាសាអង់គ្លេស-ខ្មែរ | O35: បរិញ្ញាបត្រ | R35: ថវិកាផ្ទាល់ខ្លួន | T35: បង្រៀន | U35: ខ្មែរ
A36: 35 | B36: ស សុវឌ្ឍនា | C36: Sar Sovathana | D36: ស | E36: 33520 | F36: 2910300165 | G36: 012 481 018 | H36: 34480169244010 | I36: កំពង់ចាម | J36: ខ.២.១ | K36: គ្រូឧទ្ទេស | L36: ភាសាខ្មែរ គេហវិទ្យា | M36: មធ្យមសិក្សាទុយភូមិ | N36: អក្សរសាស្រ្តខ្មែរ | O36: បរិញ្ញាបត្រជាន់ខ្ពស់ | R36: ថវិកាផ្ទាល់ខ្លួន | T36: បង្រៀន | U36: ភាសាខ្មែរ លើកកម្ពស់ភាសាជាតិ
A37: 36 | B37: កឹម សុសិទ្ធា | C37: Kem Sosethea | D37: ស | E37: 32008 | F37: 2870300157 | G37: 017 261463 | H37: 10000166473818 | I37: កំពង់ចាម | J37: ខ.២.១ | K37: គ្រូឧទ្ទេស | L37: ជីវវិទ្យា ផែនដីវិទ្យា | M37: មធ្យមសិក្សាទុយភូមិ | N37: ជីវវិទ្យា | O37: បរិញ្ញាបត្រជាន់ខ្ពស់ | R37: ថវិកាផ្ទាល់ខ្លួន | T37: បង្រៀន | U37: វិទ្យាសាស្ត្រ
A38: 37 | B38: ទិត លក្ខិណា | C38: Tith Leakhena | D38: ស | E38: 28715 | F38: 2780300027 | G38: 017 763 571 | H38: 10000166469515 | I38: កំពង់ចាម | J38: ខ.២.១ | K38: គ្រូឧទ្ទេស | L38: ភាសាអង់គ្លេស | M38: មធ្យមសិក្សាទុតិយភូមិ | N38: អក្សរសាស្ត្រខ្មែរ | O38: បរិញ្ញាបត្រ | R38: STEPCam | T38: បង្រៀន | U38: វាយតម្លៃការសិក្សា
A39: 38 | B39: ច្រឹក ធារី | C39: Chroek Theary | D39: ស | E39: 34236 | F39: 2930300284 | G39: 010 988 740 | H39: 10000250984110 | I39: កំពង់ចាម | J39: ខ.៣.៣ | K39: គ្រូឧទ្ទេស | L39: ប្រវត្តិវិទ្យា | M39: មធ្យមសិក្សាទុយភូមិ | N39: សិក្សាសង្គម | O39: បរិញ្ញាបត្រ | R39: អង្គការUNESCO | T39: បង្រៀន | U39: ការវាយតម្លៃការសិក្សា
A40: 39 | B40: ជា តុលា | C40: Chea Tola | D40: ប | E40: 34573 | F40: 1942000040 | G40: 070 840 703 | H40: 10000250829019 | I40: កំពង់ចាម | J40: ខ.៣.៣ | K40: គ្រូឧទ្ទេស | L40: អប់រំកាយ និងកីឡា | M40: មធ្យមសិក្សាទុតិយភូមិ | N40: អប់រំកាយ និងកីឡា | O40: មធ្យមសិក្សាបឋមភូមិ | T40: បង្រៀន | U40: អប់រំកាយនិងកីឡា
...
